Workbook

Sheet REMUNERACIONES
A1: REMUNERACIONES, HONORARIOS E INCENTIVOS
B3: HONORARIOS | C3: INCENTIVOS | D3: REMUNERACIONES | F3: DEDICACION | G3: MESES A | H3: TOTAL
A4: ITEM | B4: J. COMPLETA | C4: J. COMPLETA | D4: J. COMPLETA | E4: SUBTOTAL | F4: AL PROYECTO | G4: CONTRATAR | H4: PROYECTO
B5: M$/MES | C5: M$/MES | D5: M$/MES | E5: M$/MES | F5: % DE JORNADA | G5: Nº | H5: $
A6: Profesionales
A7: Scrum Master | B7: 2000000 | C7: 100000 | D7: 2100000 | E7: =SUM(B7:D7) -> 4200000 | F7: 1 | G7: 4 | H7: =+E7*F7*G7 -> 16800000
A8: Product Owner | B8: 1800000 | C8: 100000 | D8: 1900000 | E8: =SUM(B8:D8) -> 3800000 | F8: 1 | G8: 4 | H8: =+E8*F8*G8 -> 15200000
A9: Full Stack Dev | B9: 1500000 | C9: 0 | D9: 1500000 | E9: =SUM(B9:D9) -> 3000000 | F9: 1 | G9: 4 | H9: =+E9*F9*G9 -> 12000000
H10: =+E10*F10*G10 -> 0
E11: =SUM(B11:D11) -> 0 | H11: =+E11*F11*G11 -> 0
E12: =SUM(B12:D12) -> 0 | H12: =+E12*F12*G12 -> 0
E13: =SUM(B13:D13) -> 0 | H13: 0
E14: =SUM(B14:D14) -> 0 | H14: 0
E15: =SUM(B15:D15) -> 0 | H15: 0
E16: =SUM(B16:D16) -> 0 | H16: =+E16*F16*G16 -> 0
E17: =SUM(B17:D17) -> 0 | H17: =+E17*F17*G17 -> 0
A18: Personal de apoyo
E19: 0 | H19: =+E19*F19*G19 -> 0
E20: =SUM(B20:D20) -> 0 | H20: =+E20*F20*G20 -> 0
E21: =SUM(B21:D21) -> 0 | H21: =+E21*F21*G21 -> 0
E22: =SUM(B22:D22) -> 0 | H22: =+E22*F22*G22 -> 0
E23: =SUM(B23:D23) -> 0 | H23: =+E23*F23*G23 -> 0
E24: =SUM(B24:D24) -> 0 | H24: =+E24*F24*G24 -> 0
A25: SUBTOTAL | H25: =SUM(H6:H24) -> 44000000

Sheet EQUIPOS E INFRAESTRUCTURA
A1: EQUIPOS
C3: COSTO | D3: UNITARIO | E3: CANTIDAD | F3: COSTO
A4: NOMBRE DEL EQUIPO | B4: DESCRIPCIÓN | C4: CASO ADQUISICIONES | D4: CASO ARRIENDO O USO | E4: UNIDADES | F4: TOTAL
C5: M$/UNIDAD | D5: UNIDADES EXISTENTES (M$/MES) | E5: O MESES | F5: $
A6: Notebook de Desarrollo | B6: Equipo para desarrollo (i5/i7, 16GB RAM, SSD 512GB) | C6: 900000 | D6: 0 | E6: 3 unidades | F6: 2700000
A7: VPS / Servidor Cloud | B7: Hosting backend .NET + PostgreSQL (2vCPU / 4GB RAM / 80GB SSD) | C7: 0 | D7: 35.000 / mes | E7: 4 meses | F7: 175000
A8: Dominio web | B8: Registro dominio .cl por 1 año | C8: 12000 | D8: 0 | E8: 1 unidad | F8: 12000
A9: Certificado SSL | B9: SSL básico para el dominio (Let’s Encrypt es gratis, pero formalmente se incluye) | C9: 0 | D9: 0 | E9: 1 unidad | F9: 0
A10: Almacenamiento Cloudflare R2 | B10: Almacenamiento de imágenes (sitio, certificados, noticias) | C10: 0 | D10: 5.000 / mes | E10: 4 meses | F10: 25000
A11: Internet Hogar (teletrabajo) | B11: Conexión para desarrollo del proyecto | C11: 0 | D11: 30.000 / mes | E11: 4 meses × 3 estudiantes | F11: 450000
A12: Mouse + Teclado | B12: Periféricos esenciales | C12: 25000 | D12: 0 | E12: 3 unidades | F12: 75000
A13: Monitor adicional 24" | B13: Monitores para desarrollo | C13: 120000 | D13: 0 | E13: 2 unidades | F13: 240000
F14: =(+C14+D14)*E14 -> 0
F15: =(+C15+D15)*E15 -> 0
F16: =(+C16+D16)*E16 -> 0
F17: =(+C17+D17)*E17 -> 0
F18: =(+C18+D18)*E18 -> 0
F19: =(+C19+D19)*E19 -> 0
F20: =(+C20+D20)*E20 -> 0
F21: =(+C21+D21)*E21 -> 0
F22: =(+C22+D22)*E22 -> 0
F23: =(+C23+D23)*E23 -> 0
F24: =(+C24+D24)*E24 -> 0
A25: SUBTOTAL | F25: =SUM(F6:F24) -> 3677000
A29: INFRAESTRUCTURA
C31: COSTO | D31: UNITARIO | E31: CANTIDAD | F31: COSTO
A32: NOMBRE DE LA INFRAESTRUCTURA | B32: DESCRIPCIÓN | C32: CASO ADQUISICIONES | D32: CASO ARRIENDO O USO | E32: UNIDADES | F32: TOTAL
C33: O HABILITACIÓNM$/UNIDAD | D33: UNIDADES EXISTENTES (M$/MES) | E33: O MESES | F33: $
A34: Espacio de trabajo colaborativo (Cowork) | B34: Uso de sala para reuniones, planificación y desarrollo | C34: 0 | D34: 120.000 / mes | E34: 5 meses | F34: 600000
A35: Electricidad e insumos operacionales | B35: Costos de energía para equipos, carga de notebooks y periféricos | C35: 0 | D35: 10.000 / mes | E35: 5 meses | F35: 50000
A36: Servicio de Internet de alta velocidad | B36: Conectividad estable necesaria para desarrollo y despliegue | C36: 0 | D36: 25.000 / mes | E36: 5 meses | F36: 125000
A37: Espacio servidor / rack virtual | B37: Infraestructura física en datacenter (equivalente a hosting físico) | C37: 0 | D37: 20.000 / mes | E37: 5 meses | F37: 100000
A38: Mobiliario básico (mesas y sillas) | B38: Habilitación física mínima | C38: 150000 | D38: 0 | E38: 3 unidades | F38: 450000
A39: Sala de reuniones (institución o arriendo) | B39: Uso esporádico para sprint reviews y planning | C39: 0 | D39: 15.000 / mes | E39: 5 meses | F39: 75000
A40: Licencias infraestructura de red | B40: Firewall, VPN, protección y acceso seguro (versión básica educativa) | C40: 0 | D40: 10.000 / mes | E40: 5 meses | F40: 50000
F41: =(+C41+D41)*E41 -> 0
F42: =(+C42+D42)*E42 -> 0
A43: SUBTOTAL | F43: =SUM(F34:F42) -> 1450000

Sheet SOFTWARE Y FUNGIBLES
A1: SOFTWARE
B3: COSTO | D3: COSTO
A4: DESCRIPCIÓN | B4: UNITARIO | C4: CANTIDAD | D4: TOTAL
B5: M$/UNIDAD | D5: $
A6: Cloudflare R2 (Storage) | B6: 5.000 / mes | C6: 4 | D6: 25000
A7: VPS (2 vCPU / 4GB RAM / 80GB SSD) | B7: 35.000 / mes | C7: 4 | D7: 175000
A8: Dominio .cl | B8: 12.000 anual | C8: 1 | D8: 12000
A9: Certificado SSL (Cloudflare/Let's Encrypt) | B9: 0 | C9: 1 | D9: 0
A10: GitHub (repositorio privado) | B10: 0 (plan free) | C10: 1 | D10: 0
A11: Visual Studio Code | B11: 0 | C11: 1 | D11: 0
A12: PostgreSQL / PGAdmin | B12: 0 | C12: 1 | D12: 0
A13: Netlify (Hosting Frontend) | B13: 0 | C13: 4 | D13: 0
A14: SUBTOTAL | D14: =SUM(D6:D10) -> 212000
A20: FUNGIBLES
B22: COSTO | D22: COSTO
A23: DESCRIPCIÓN | B23: UNITARIO | C23: CANTIDAD | D23: TOTAL
B24: M$/UNIDAD | D24: $
A25: Cuadernos y libretas para reuniones | B25: 2000 | C25: 5 | D25: 10000
A26: Lápices (set 12 unidades) | B26: 1500 | C26: 3 | D26: 4500
A27: Post-it para planificación (Scrum) | B27: 3000 | C27: 5 | D27: 15000
A28: Marcadores de pizarra | B28: 2000 | C28: 4 | D28: 8000
A29: Hojas impresas para documentación | B29: 5.000 / resma | C29: 1 | D29: 5000
A30: Cartulinas o láminas para diagramas | B30: 1000 | C30: 5 | D30: 5000
A31: Tinta / Impresiones (uso mensual) | B31: 5000 | C31: 5 | D31: 25000
A32: Alcohol gel y limpieza del área | B32: 2000 | C32: 5 | D32: 10000
A33: Cinta adhesiva / masking tape | B33: 800 | C33: 3 | D33: 2400
A34: Carpetas o archivadores | B34: 1000 | C34: 4 | D34: 4000
D35: =+B35*C35 -> 0
D36: =+B36*C36 -> 0
D37: =+B37*C37 -> 0
D38: =+B38*C38 -> 0
A39: SUBTOTAL | D39: =SUM(D25:D38) -> 88900

Sheet OTROS
A2: PROPIEDAD INTELECTUAL
B4: COSTO | D4: COSTO
A5: DESCRIPCIÓN | B5: UNITARIO | C5: CANTIDAD | D5: TOTAL
B6: M$/UNIDAD | D6: $
A7: DESCRIPCIÓN | B7: COSTO UNITARIO (M$ / UNIDAD) | C7: CANTIDAD | D7: COSTO TOTAL ($)
A8: Registro de marca “SITECOM” en INAPI | B8: 60000 | C8: 1 | D8: 60000
A9: Registro del software en INAPI (derechos de autor) | B9: 30000 | C9: 1 | D9: 30000
A10: Asesoría legal básica para propiedad intelectual (opcional) | B10: 50000 | C10: 1 | D10: 50000
A11: Redacción de contrato de cesión o titularidad del software | B11: 20000 | C11: 1 | D11: 20000
A12: SUBTOTAL | D12: =SUM(D7:D11) -> 160000
A15: GASTOS GENERALES E IMPREVISTOS
B17: COSTO | D17: COSTO
A18: DESCRIPCIÓN | B18: UNITARIO | C18: CANTIDAD | D18: TOTAL
B19: M$/UNIDAD | D19: $
A20: Movilización del equipo (reuniones, visitas) | B20: 3000 | C20: 10 | D20: 30000
A21: Alimentación en jornadas de trabajo extensas | B21: 7000 | C21: 5 | D21: 35000
A22: Imprevistos varios (adaptadores, cables, pérdidas, daños menores) | B22: 10000 | C22: 1 | D22: 10000
A23: Contingencia del proyecto (2% del presupuesto estimado) | B23: 20000 | C23: 1 | D23: 20000
A24: Servicios menores (fotocopias, trámites, certificados) | B24: 5000 | C24: 3 | D24: 15000
A25: SUBTOTAL | D25: =SUM(D20:D24) -> 110000
A31: GASTOS COMUNES
A33: DESCRIPCIÓN | B33: COSTO | D33: COSTO
B34: UNITARIO | C34: CANTIDAD | D34: TOTAL
B35: M$/UNIDAD | D35: $
A36: Internet Hogar (uso compartido por el equipo) | B36: 12.000 / mes | C36: 5 meses | D36: 60000
A37: Luz / Electricidad para equipos de trabajo | B37: 10.000 / mes | C37: 5 meses | D37: 50000
A38: Servicios administrativos (impresiones, trámites varios) | B38: 5000 | C38: 5 | D38: 25000
A39: Material de oficina básico (papel, carpetas, clips) | B39: 3000 | C39: 5 | D39: 15000
A40: Uso de espacios comunes (cowork / biblioteca / salas DUOC) | B40: 5.000 / mes | C40: 5 meses | D40: 25000
A41: Gastos de comunicación (llamadas, mensajes, coordinación) | B41: 3000 | C41: 5 | D41: 15000
A42: Agua / Café / Insumos de reuniones | B42: 3000 | C42: 5 | D42: 15000
D43: =+B43*C43 -> 0
D44: =+B44*C44 -> 0
A45: SUBTOTAL | D45: =SUM(D36:D44) -> 205000
A53: GASTOS DE MANTENIMIENTO
B55: COSTO | D55: COSTO
A56: DESCRIPCIÓN | B56: UNITARIO | C56: CANTIDAD | D56: TOTAL
B57: M$/UNIDAD | D57: $
D58: =+B58*C58 -> 0
D59: =+B59*C59 -> 0
...

Sheet TOTAL
A1: COSTO TOTAL DEL PROYECTO MED SENSE
B4: COSTO
A5: ITEM | B5: TOTAL
B6: $
A7: HONORARIOS, INCENTIVOS, REMUNERACIONES | B7: =REMUNERACIONES!H25 -> 44000000
A8: EQUIPOS | B8: ='EQUIPOS E INFRAESTRUCTURA'!F25 -> 3677000
A9: INFRAESTRUCTURA | B9: ='EQUIPOS E INFRAESTRUCTURA'!F43 -> 1450000
A10: SOFTWARE | B10: ='SOFTWARE Y FUNGIBLES'!D14 -> 212000
A11: PROPIEDAD INTELECTUAL | B11: =OTROS!D12 -> 160000
A12: GASTOS COMUNES | B12: =OTROS!D45 -> 205000
A13: GASTOS GENERALES E IMPREVISTOS | B13: =OTROS!D25 -> 110000
A14: TOTAL | B14: =SUM(B7:B13) -> 49814000
